<?xml version="1.0" ?>
<!-- =================================================================================== -->
<!-- |    This document was autogenerated by xacro from five_dof_arm.xacro             | -->
<!-- |    EDITING THIS FILE BY HAND IS NOT RECOMMENDED                                 | -->
<!-- =================================================================================== -->
<robot name="five_dof_arm" xmlns:xacro="http://www.ros.org/wiki/xacro">
  <material name="Black">
    <color rgba="0.0 0.0 0.0 1.0"/>
  </material>
  <material name="White">
    <color rgba="1.0 1.0 1.0 1.0"/>
  </material>
  <material name="Blue">
    <color rgba="0 0 1.0 0"/>
  </material>
  <material name="Green">
    <color rgba="0 1.0 0 1.0"/>
  </material>
  <material name="Red">
    <color rgba="1.0 0 0 0"/>
  </material>
  <!-- Macros (no use of the new feature letting you put more than one visual property to a link) -->
  <!--/////////////////////////////////////////////////////////////////-->
  <!-- ALWAYS HAVE A BASE_LINK NAMED EXACTLY THIS WAY OR IT WON'T COMPILE THE TF -->
  <joint name="bottom_joint" type="fixed">
    <origin rpy="0 0 0" xyz="0 0 0"/>
    <parent link="map"/>
    <child link="base_link"/>
  </joint>
  <link name="map">
    <visual>
      <origin rpy="0 0 0" xyz=" 0 0 -0.01"/>
      <geometry>
        <box size="1 1 0.02"/>
      </geometry>
      <material name="Black"/>
    </visual>
    <collision>
      <origin rpy="0 0 0" xyz=" 0 0 -0.01"/>
      <geometry>
        <box size="1 1 0.02"/>
      </geometry>
    </collision>
  </link>
  <gazebo reference="bottom_link">
    <material>Gazebo/Gray</material>
  </gazebo>
  <link name="base_link">
    <visual>
      <origin rpy="0 0 0" xyz="0 0 0.017"/>
      <geometry>
        <box size="0.1 0.1 0.03"/>
      </geometry>
      <material name="White"/>
    </visual>
    <inertial>
      <mass value="1"/>
      <inertia ixx="1.0" ixy="0.0" ixz="0.0" iyy="0.5" iyz="0.0" izz="1.0"/>
    </inertial>
    <collision>
      <origin rpy="0 0 0" xyz="0 0 0.017"/>
      <geometry>
        <box size="0.1 0.1 0.03"/>
      </geometry>
    </collision>
  </link>
  <joint name="base_joint" type="fixed">
    <parent link="base_link"/>
    <child link="base_link_2"/>
    <origin xyz="0 -0.035 0.015"/>
  </joint>
  <link name="base_link_2">
    <visual>
      <origin rpy="0 0 0" xyz="0 0 0.03"/>
      <geometry>
        <box size="0.1 0.03 0.06"/>
      </geometry>
      <material name="White"/>
    </visual>
    <inertial>
      <mass value="1"/>
      <inertia ixx="1.0" ixy="0.0" ixz="0.0" iyy="0.5" iyz="0.0" izz="1.0"/>
    </inertial>
    <collision>
      <origin rpy="0 0 0" xyz="0 0 0.03"/>
      <geometry>
        <box size="0.1 0.03 0.06"/>
      </geometry>
    </collision>
  </link>
  <joint name="base_joint_2" type="fixed">
    <parent link="base_link_2"/>
    <child link="servo_1_support_1"/>
    <origin xyz="0 0.015 0.035"/>
  </joint>
  <link name="servo_1_support_1">
    <visual>
      <origin rpy="0 0 0" xyz="0 0.001 0.025"/>
      <geometry>
        <box size="0.0375 0.0020 0.035"/>
      </geometry>
      <material name="White"/>
    </visual>
    <inertial>
      <mass value="1"/>
      <inertia ixx="1.0" ixy="0.0" ixz="0.0" iyy="0.5" iyz="0.0" izz="1.0"/>
    </inertial>
  </link>
  <joint name="servo_1_support_2" type="fixed">
    <parent link="servo_1_support_1"/>
    <child link="servo_1_support_3"/>
    <origin rpy="0 0 0" xyz="0 0.0 0.0075"/>
  </joint>
  <link name="servo_1_support_3">
    <visual>
      <origin rpy="0 0 0" xyz="0 0.015 0"/>
      <geometry>
        <box size="0.0375 0.03 0.002"/>
      </geometry>
      <material name="White"/>
    </visual>
    <inertial>
      <mass value="1"/>
      <inertia ixx="1.0" ixy="0.0" ixz="0.0" iyy="0.5" iyz="0.0" izz="1.0"/>
    </inertial>
  </link>
  <joint name="servo_1_support_X" type="fixed">
    <parent link="servo_1_support_1"/>
    <child link="servo_1"/>
    <origin rpy="0 0 0" xyz="0 0.003 0.025"/>
  </joint>
  <link name="servo_1">
    <collision>
      <origin rpy="0 0 0" xyz="0 0.01175 0.006"/>
      <geometry>
        <box size="0.05 0.0335 0.055"/>
      </geometry>
    </collision>
    <visual>
      <origin rpy="0 0 0" xyz="0 0.01175 0.006"/>
      <geometry>
        <box size="0.045 0.0235 0.04"/>
      </geometry>
      <material name="Black"/>
    </visual>
    <inertial>
      <mass value="1"/>
      <inertia ixx="1.0" ixy="0.0" ixz="0.0" iyy="0.5" iyz="0.0" izz="1.0"/>
    </inertial>
  </link>
  <gazebo reference="servo_1">
    <material>Gazebo/Black</material>
  </gazebo>
  <joint name="servo_1_1" type="revolute">
    <parent link="servo_1"/>
    <child link="servo_1_2"/>
    <origin rpy="0 0 0" xyz="0.01 0.01175 0.026"/>
    <axis xyz="0 0 1"/>
    <limit effort="300" lower="0" upper="3.14159" velocity="1"/>
    <dynamics damping="50" friction="1"/>
  </joint>
  <transmission name="tran1">
    <type>transmission_interface/SimpleTransmission</type>
    <joint name="servo_1_1">
      <hardwareInterface>PositionJointInterface</hardwareInterface>
    </joint>
    <actuator name="motor1">
      <hardwareInterface>PositionJointInterface</hardwareInterface>
      <mechanicalReduction>1</mechanicalReduction>
    </actuator>
  </transmission>
  <link name="servo_1_2">
    <visual>
      <origin rpy="0 0 0" xyz="0 0 0.0025"/>
      <geometry>
        <cylinder length="0.005" radius="0.005"/>
      </geometry>
      <material name="Black"/>
    </visual>
    <inertial>
      <mass value="1"/>
      <inertia ixx="1.0" ixy="0.0" ixz="0.0" iyy="0.5" iyz="0.0" izz="1.0"/>
    </inertial>
  </link>
  <gazebo reference="servo_1_2">
    <material>Gazebo/Black</material>
  </gazebo>
  <joint name="servo_1_3" type="fixed">
    <parent link="servo_1_2"/>
    <child link="servo_1_4"/>
    <origin rpy="0 0 0" xyz="0 0 0.0025"/>
  </joint>
  <link name="servo_1_4">
    <visual>
      <origin rpy="0 0 0" xyz="0 0 0.0025"/>
      <geometry>
        <cylinder length="0.005" radius="0.01"/>
      </geometry>
      <material name="Black"/>
    </visual>
    <inertial>
      <mass value="1"/>
      <inertia ixx="1.0" ixy="0.0" ixz="0.0" iyy="0.5" iyz="0.0" izz="1.0"/>
    </inertial>
  </link>
  <gazebo reference="servo_1_4">
    <material>Gazebo/Black</material>
  </gazebo>
  <!-- From now on, we use more than one visual property per link up to a revolute joint -->
  <joint name="servo_2_1" type="fixed">
    <parent link="servo_1_4"/>
    <child link="servo_2"/>
    <origin rpy="0 0 0" xyz="0 0 0.005"/>
  </joint>
  <link name="servo_2">
    <visual>
      <origin rpy="0 0 0" xyz="0 0 0.001"/>
      <geometry>
        <box size="0.045 0.0375 0.002"/>
      </geometry>
      <material name="White"/>
    </visual>
    <visual>
      <origin rpy="0 0 0" xyz="0.0225 0 0.015"/>
      <geometry>
        <box size="0.002 0.0375 0.03"/>
      </geometry>
      <material name="White"/>
    </visual>
    <visual>
      <origin rpy="0 0 0" xyz="0 0 0.01375"/>
      <geometry>
        <box size="0.04 0.045 0.0235"/>
      </geometry>
      <material name="Black"/>
    </visual>
    <visual>
      <origin rpy="0 1.570795 0" xyz="-0.0225 -0.01 0.01375"/>
      <geometry>
        <cylinder length="0.005" radius="0.005"/>
      </geometry>
      <material name="Black"/>
    </visual>
    <visual>
      <origin rpy="0 1.570795 0" xyz="-0.0275 -0.01 0.01375"/>
      <geometry>
        <cylinder length="0.005" radius="0.01"/>
      </geometry>
      <material name="Black"/>
    </visual>
    <inertial>
      <mass value="1"/>
      <inertia ixx="1.0" ixy="0.0" ixz="0.0" iyy="0.5" iyz="0.0" izz="1.0"/>
    </inertial>
    <collision>
      <origin rpy="0 0 0" xyz="-0.005 0 0.01375"/>
      <geometry>
        <box size="0.055 0.055 0.0335"/>
      </geometry>
    </collision>
  </link>
  <gazebo reference="servo_2">
    <material>Gazebo/Black</material>
  </gazebo>
  <joint name="servo_2_2" type="revolute">
    <parent link="servo_2"/>
    <child link="bicep"/>
    <origin rpy="0 0 0" xyz="-0.03 -0.01 0.01375"/>
    <axis xyz="1 0 0"/>
    <limit effort="300" lower="-1.570795" upper="1.570795" velocity="1"/>
    <dynamics damping="50" friction="1"/>
  </joint>
  <transmission name="tran1">
    <type>transmission_interface/SimpleTransmission</type>
    <joint name="servo_2_2">
      <hardwareInterface>PositionJointInterface</hardwareInterface>
    </joint>
    <actuator name="motor1">
      <hardwareInterface>PositionJointInterface</hardwareInterface>
      <mechanicalReduction>1</mechanicalReduction>
    </actuator>
  </transmission>
  <link name="bicep">
    <visual>
      <origin rpy="0 1.570795 0" xyz="-0.0015 0 0"/>
      <geometry>
        <cylinder length="0.003" radius="0.0125"/>
      </geometry>
      <material name="White"/>
    </visual>
    <visual>
      <origin rpy="0 1.570795 0" xyz="0.0565 0 0"/>
      <geometry>
        <cylinder length="0.003" radius="0.0125"/>
      </geometry>
      <material name="White"/>
    </visual>
    <visual>
      <origin rpy="0 0 0" xyz="-0.0015 0 0.05"/>
      <geometry>
        <box size="0.003 0.025 0.1"/>
      </geometry>
      <material name="White"/>
    </visual>
    <visual>
      <origin rpy="0 0 0" xyz="0.0565 0 0.05"/>
      <geometry>
        <box size="0.003 0.025 0.1"/>
      </geometry>
      <material name="White"/>
    </visual>
    <visual>
      <origin rpy="0 1.570795 0" xyz="-0.0015 0 0.1"/>
      <geometry>
        <cylinder length="0.003" radius="0.0125"/>
      </geometry>
      <material name="White"/>
    </visual>
    <visual>
      <origin rpy="0 1.570795 0" xyz="0.0565 0 0.1"/>
      <geometry>
        <cylinder length="0.003" radius="0.0125"/>
      </geometry>
      <material name="White"/>
    </visual>
    <inertial>
      <mass value="1"/>
      <inertia ixx="1.0" ixy="0.0" ixz="0.0" iyy="0.5" iyz="0.0" izz="1.0"/>
    </inertial>
    <collision>
      <origin rpy="0 0 0" xyz="0.0275 0 0.01375"/>
      <geometry>
        <box size="0.063 0.03 0.14"/>
      </geometry>
    </collision>
  </link>
  <joint name="servo_3_1" type="revolute">
    <parent link="bicep"/>
    <child link="servo_3"/>
    <origin rpy="0 0 0" xyz="0 0 0.1"/>
    <axis xyz="1 0 0"/>
    <limit effort="300" lower="-1.570795" upper="0.39269875" velocity="1"/>
    <dynamics damping="50" friction="1"/>
  </joint>
  <transmission name="tran1">
    <type>transmission_interface/SimpleTransmission</type>
    <joint name="servo_3_1">
      <hardwareInterface>PositionJointInterface</hardwareInterface>
    </joint>
    <actuator name="motor1">
      <hardwareInterface>PositionJointInterface</hardwareInterface>
      <mechanicalReduction>1</mechanicalReduction>
    </actuator>
  </transmission>
  <link name="servo_3">
    <visual>
      <origin rpy="0 0 0" xyz="0.03 0.01375 0.01"/>
      <geometry>
        <box size="0.045 0.002 0.0375"/>
      </geometry>
      <material name="White"/>
    </visual>
    <visual>
      <origin rpy="0 0 0" xyz="0.0525 -0.00125 0.012"/>
      <geometry>
        <box size="0.002 0.03 0.0375"/>
      </geometry>
      <material name="White"/>
    </visual>
    <visual>
      <origin rpy="-1.570795 0 0" xyz="0.03 0 0.01"/>
      <geometry>
        <box size="0.04 0.045 0.0235"/>
      </geometry>
      <material name="Black"/>
    </visual>
    <visual>
      <origin rpy="0 1.570795 0" xyz="0.0075 0 0"/>
      <geometry>
        <cylinder length="0.005" radius="0.005"/>
      </geometry>
      <material name="Black"/>
    </visual>
    <visual>
      <origin rpy="0 1.570795 0" xyz="0.0025 0 0"/>
      <geometry>
        <cylinder length="0.005" radius="0.01"/>
      </geometry>
      <material name="Black"/>
    </visual>
    <visual>
      <origin rpy="1.570795 0 0" xyz="0.03 0.01675 0.0125"/>
      <geometry>
        <cylinder length="0.003" radius="0.01"/>
      </geometry>
      <material name="White"/>
    </visual>
    <visual>
      <origin rpy="0 0 0" xyz="0.03 0.01675 0.024"/>
      <geometry>
        <box size="0.02 0.003 0.03"/>
      </geometry>
      <material name="White"/>
    </visual>
    <visual>
      <origin rpy="0 0 0" xyz="0.03 0.00475 0.04"/>
      <geometry>
        <box size="0.02 0.027 0.003"/>
      </geometry>
      <material name="White"/>
    </visual>
    <visual>
      <origin rpy="0 0 0" xyz="0.03 -0.00125 0.04"/>
      <geometry>
        <cylinder length="0.003" radius="0.01"/>
      </geometry>
      <material name="White"/>
    </visual>
    <inertial>
      <mass value="1"/>
      <inertia ixx="1.0" ixy="0.0" ixz="0.0" iyy="0.5" iyz="0.0" izz="1.0"/>
    </inertial>
    <collision>
      <origin rpy="0 0 0" xyz="0.03 0 0.01"/>
      <geometry>
        <box size="0.06 0.03 0.05"/>
      </geometry>
    </collision>
  </link>
  <gazebo reference="servo_3">
    <material>Gazebo/Black</material>
  </gazebo>
  <joint name="useless_joint" type="fixed">
    <parent link="servo_3"/>
    <child link="servo_4_support_1"/>
    <origin rpy="0 0 0" xyz="0.03 -0.00325 0.0415"/>
  </joint>
  <link name="servo_4_support_1">
    <visual>
      <origin rpy="0 0 0" xyz="-0.005 -0.01 0.018"/>
      <geometry>
        <box size="0.0375 0.0020 0.035"/>
      </geometry>
      <material name="White"/>
    </visual>
    <inertial>
      <mass value="1"/>
      <inertia ixx="1.0" ixy="0.0" ixz="0.0" iyy="0.5" iyz="0.0" izz="1.0"/>
    </inertial>
  </link>
  <joint name="servo_4_support_2" type="fixed">
    <parent link="servo_4_support_1"/>
    <child link="servo_4_support_3"/>
    <origin rpy="0 0 0" xyz="-0.005 -0.011 0.0005"/>
  </joint>
  <link name="servo_4_support_3">
    <visual>
      <origin rpy="0 0 0" xyz="0 0.015 0"/>
      <geometry>
        <box size="0.0375 0.03 0.002"/>
      </geometry>
      <material name="White"/>
    </visual>
    <inertial>
      <mass value="1"/>
      <inertia ixx="1.0" ixy="0.0" ixz="0.0" iyy="0.5" iyz="0.0" izz="1.0"/>
    </inertial>
  </link>
  <joint name="servo_4_support_X" type="fixed">
    <parent link="servo_4_support_1"/>
    <child link="servo_4"/>
    <origin rpy="0 0 0" xyz="-0.005 -0.008 0.018"/>
  </joint>
  <link name="servo_4">
    <collision>
      <origin rpy="0 0 0" xyz="0 0.01175 0.006"/>
      <geometry>
        <box size="0.05 0.0335 0.055"/>
      </geometry>
    </collision>
    <visual>
      <origin rpy="0 0 0" xyz="0 0.01175 0.006"/>
      <geometry>
        <box size="0.045 0.0235 0.04"/>
      </geometry>
      <material name="Black"/>
    </visual>
    <inertial>
      <mass value="1"/>
      <inertia ixx="1.0" ixy="0.0" ixz="0.0" iyy="0.5" iyz="0.0" izz="1.0"/>
    </inertial>
  </link>
  <gazebo reference="servo_4">
    <material>Gazebo/Black</material>
  </gazebo>
  <joint name="servo_4_1" type="revolute">
    <parent link="servo_4"/>
    <child link="servo_4_2"/>
    <origin rpy="0 0 0" xyz="0.01 0.01175 0.026"/>
    <axis xyz="0 0 1"/>
    <limit effort="300" lower="0" upper="3.14159" velocity="1"/>
    <dynamics damping="50" friction="1"/>
  </joint>
  <transmission name="tran1">
    <type>transmission_interface/SimpleTransmission</type>
    <joint name="servo_4_1">
      <hardwareInterface>PositionJointInterface</hardwareInterface>
    </joint>
    <actuator name="motor1">
      <hardwareInterface>PositionJointInterface</hardwareInterface>
      <mechanicalReduction>1</mechanicalReduction>
    </actuator>
  </transmission>
  <link name="servo_4_2">
    <visual>
      <origin rpy="0 0 0" xyz="0 0 0.0025"/>
      <geometry>
        <cylinder length="0.005" radius="0.005"/>
      </geometry>
      <material name="Black"/>
    </visual>
    <inertial>
      <mass value="1"/>
      <inertia ixx="1.0" ixy="0.0" ixz="0.0" iyy="0.5" iyz="0.0" izz="1.0"/>
    </inertial>
  </link>
  <gazebo reference="servo_4_2">
    <material>Gazebo/Black</material>
  </gazebo>
  <joint name="servo_4_3" type="fixed">
    <parent link="servo_4_2"/>
    <child link="servo_4_4"/>
    <origin rpy="0 0 0" xyz="0 0 0.0025"/>
  </joint>
  <link name="servo_4_4">
    <visual>
      <origin rpy="0 0 0" xyz="0 0 0.0025"/>
      <geometry>
        <cylinder length="0.005" radius="0.01"/>
      </geometry>
      <material name="Black"/>
    </visual>
    <inertial>
      <mass value="1"/>
      <inertia ixx="1.0" ixy="0.0" ixz="0.0" iyy="0.5" iyz="0.0" izz="1.0"/>
    </inertial>
  </link>
  <gazebo reference="servo_4_4">
    <material>Gazebo/Black</material>
  </gazebo>
  <joint name="claw_to_wrist" type="fixed">
    <parent link="servo_4_4"/>
    <child link="claw_palm"/>
    <origin rpy="0 0 0" xyz="0 0 0.0025"/>
  </joint>
  <link name="claw_palm">
    <visual>
      <origin rpy="0 0 0" xyz="0 0 0.01"/>
      <geometry>
        <cylinder length="0.02" radius="0.03"/>
      </geometry>
      <material name="White"/>
    </visual>
    <inertial>
      <mass value="1"/>
      <inertia ixx="1.0" ixy="0.0" ixz="0.0" iyy="0.5" iyz="0.0" izz="1.0"/>
    </inertial>
    <collision>
      <origin rpy="0 0 0" xyz="0 0 0.01"/>
      <geometry>
        <cylinder length="0.02" radius="0.03"/>
      </geometry>
    </collision>
  </link>
  <joint name="claw_joint_1" type="revolute">
    <parent link="claw_palm"/>
    <child link="claw_1"/>
    <origin rpy="0 0 0" xyz="0.01 0 0.01"/>
    <axis xyz="0 -1 0"/>
    <limit effort="300" lower="0" upper="0.39269875" velocity="1"/>
    <dynamics damping="50" friction="1"/>
  </joint>
  <joint name="claw_joint_2" type="revolute">
    <parent link="claw_palm"/>
    <child link="claw_2"/>
    <origin rpy="0 0 0" xyz="-0.01 0 0.01"/>
    <axis xyz="0 1 0"/>
    <limit effort="300" lower="0" upper="0.39269875" velocity="1"/>
    <dynamics damping="50" friction="1"/>
  </joint>
  <link name="claw_1">
    <visual>
      <origin rpy="0 0 0" xyz="0.0135 0 0.03"/>
      <geometry>
        <cylinder length="0.06" radius="0.003"/>
      </geometry>
      <material name="Black"/>
    </visual>
    <inertial>
      <mass value="1"/>
      <inertia ixx="1.0" ixy="0.0" ixz="0.0" iyy="0.5" iyz="0.0" izz="1.0"/>
    </inertial>
    <collision>
      <origin rpy="0 0 0" xyz="0.0135 0 0.02"/>
      <geometry>
        <cylinder length="0.04" radius="0.003"/>
      </geometry>
    </collision>
  </link>
  <gazebo reference="claw_1">
    <material>Gazebo/Black</material>
  </gazebo>
  <link name="claw_2">
    <visual>
      <origin rpy="0 0 0" xyz="-0.0135 0 0.03"/>
      <geometry>
        <cylinder length="0.06" radius="0.003"/>
      </geometry>
      <material name="Black"/>
    </visual>
    <inertial>
      <mass value="1"/>
      <inertia ixx="1.0" ixy="0.0" ixz="0.0" iyy="0.5" iyz="0.0" izz="1.0"/>
    </inertial>
    <collision>
      <origin rpy="0 0 0" xyz="-0.0135 0 0.02"/>
      <geometry>
        <cylinder length="0.04" radius="0.003"/>
      </geometry>
    </collision>
  </link>
  <gazebo reference="claw_2">
    <material>Gazebo/Black</material>
  </gazebo>
  <gazebo>
    <plugin filename="libgazebo_ros_control.so" name="gazebo_ros_control">
      <robotNamespace>/five_dof_arm</robotNamespace>
    </plugin>
  </gazebo>
  <link name="grasping_frame">
    <inertial>
      <origin rpy="0 0 0" xyz="0 0 0"/>
      <mass value="0.0001"/>
      <cuboid_inertia mass="0.0001" x="0.001" y="0.001" z="0.001"/>
      <inertia ixx="1.0" ixy="0.0" ixz="0.0" iyy="100.0" iyz="0.0" izz="1.0"/>
    </inertial>
    <visual>
      <origin xyz="0 0 0.01"/>
      <geometry>
        <box size="0.01 0.01 0.01"/>
      </geometry>
      <material name="White"/>
    </visual>
  </link>
  <joint name="grasping_frame_joint" type="fixed">
    <parent link="claw_palm"/>
    <child link="grasping_frame"/>
    <origin rpy="0 0 0" xyz="0 0 0.06"/>
  </joint>
</robot>

